Report for assignment1.py start evaluation at <built-in method now of type object at 0x7f2f7bcc8900>
Errors occurred during run at <built-in method now of type object at 0x7f2f7bcc8900>!
b'Traceback (most recent call last):\n  File "assignment1.py", line 45, in <module>\n    results = pool.map(todo, ids)\n  File "/commons/conda/lib/python3.8/multiprocessing/pool.py", line 364, in map\n    return self._map_async(func, iterable, mapstar, chunksize).get()\n  File "/commons/conda/lib/python3.8/multiprocessing/pool.py", line 771, in get\n    raise self._value\n  File "/commons/conda/lib/python3.8/multiprocessing/pool.py", line 125, in worker\n    result = (True, func(*args, **kwds))\n  File "/commons/conda/lib/python3.8/multiprocessing/pool.py", line 48, in mapstar\n    return list(map(*args))\n  File "assignment1.py", line 34, in todo\n    handle = Entrez.efetch(db="pubmed", id=x, retmode="xml")\n  File "/commons/conda/lib/python3.8/site-packages/Bio/Entrez/__init__.py", line 207, in efetch\n    return _open(cgi, variables, post=post)\n  File "/commons/conda/lib/python3.8/site-packages/Bio/Entrez/__init__.py", line 606, in _open\n    handle = urlopen(cgi)\n  File "/commons/conda/lib/python3.8/urllib/request.py", line 222, in urlopen\n    return opener.open(url, data, timeout)\n  File "/commons/conda/lib/python3.8/urllib/request.py", line 531, in open\n    response = meth(req, response)\n  File "/commons/conda/lib/python3.8/urllib/request.py", line 640, in http_response\n    response = self.parent.error(\n  File "/commons/conda/lib/python3.8/urllib/request.py", line 569, in error\n    return self._call_chain(*args)\n  File "/commons/conda/lib/python3.8/urllib/request.py", line 502, in _call_chain\n    result = func(*args)\n  File "/commons/conda/lib/python3.8/urllib/request.py", line 649, in http_error_default\n    raise HTTPError(req.full_url, code, msg, hdrs, fp)\nurllib.error.HTTPError: HTTP Error 429: Too Many Requests\n'
*** ASSIGNMENT assignment1.py STATUS: FAILED ***
